<mujoco model="six_dof_arm">
    <compiler angle="radian" coordinate="local"/>
    <option gravity="0 0 -9.81" timestep="0.001"/>
    <!-- 积分器使用 RK4，步长小但可能仍然不够稳：RK4 精度高但容易震荡，搭配高 kp 时数值不稳定。 -->
    <!-- <option gravity="0 0 -9.81" integrator="RK4" timestep="0.001"/> -->
  
    <default>
      <joint limited="true" damping="10"/>
      <geom type="capsule" size="0.03" rgba="0.6 0.6 0.9 1"/>
    </default>
  
    <worldbody>
      <!-- 地面 -->
      <geom name="floor" type="plane" pos="0 0 0" size="3 3 0.1" rgba="0.9 0.9 0.9 1"/>
  
      <body name="base" pos="0 0 0">
        <!-- 1号关节 -->
        <joint name="joint1" type="hinge" axis="0 0 1" range="-3.14 3.14"/>
        <geom type="capsule" size="0.03" fromto="0 0 0 0 0 0.3"/>
  
        <!-- 2号关节 -->
        <body pos="0 0 0.3">
          <joint name="joint2" type="hinge" axis="0 1 0" range="-3.14 3.14"/>
          <geom type="capsule" size="0.03" fromto="0 0 0 0 0 0.3"/>
  
          <!-- 3号关节 -->
          <body pos="0 0 0.3">
            <joint name="joint3" type="hinge" axis="0 1 0" range="-3.14 3.14"/>
            <geom type="capsule" size="0.03" fromto="0 0 0 0 0 0.3"/>
  
            <!-- 4号关节 -->
            <body pos="0 0 0.3">
              <joint name="joint4" type="hinge" axis="1 0 0" range="-3.14 3.14"/>
              <geom type="capsule" size="0.03" fromto="0 0 0 0 0 0.3"/>
  
              <!-- 5号关节 -->
              <body pos="0 0 0.3">
                <joint name="joint5" type="hinge" axis="0 1 0" range="-3.14 3.14"/>
                <geom type="capsule" size="0.03" fromto="0 0 0 0 0 0.3"/>
  
                <!-- 6号关节 -->
                <body pos="0 0 0.3">
                  <joint name="joint6" type="hinge" axis="1 0 0" range="-3.14 3.14"/>
                  <geom type="capsule" size="0.03" fromto="0 0 0 0 0 0.3"/>
  
                  <!-- 末端执行器 -->
                  <site name="ee_site" pos="0 0 0.3" size="0.02" rgba="1 0 0 1"/>
                </body>
              </body>
            </body>
          </body>
        </body>
      </body>
    </worldbody>
  
    <actuator>
      <position joint="joint1" kp="2000"/>
      <position joint="joint2" kp="2000"/>
      <position joint="joint3" kp="2000"/>
      <position joint="joint4" kp="2000"/>
      <position joint="joint5" kp="2000"/>
      <position joint="joint6" kp="2000"/>
    </actuator>
  </mujoco>
  